Workbook

Sheet Summary P&L
B2: Proposed Carpet | C2: =C18/1.2 -> 2373.2933 | D2: =D18/1.2 -> 2700.6441 | E2: =E18/1.2 -> 2782.4818 | F2: =F18/1.2 -> 2864.3195 | G2: =G18/1.2 -> 2946.1572
B3: Additional Area in Carpet | C3: =C16*C4/1.2 -> 736.5393 | D3: =D16*D4/1.2 -> 1063.8901 | E3: =E16*E4/1.2 -> 1145.7278 | F3: =F16*F4/1.2 -> 1227.5655 | G3: =G16*G4/1.2 -> 1309.4032
C4: 0.45 | D4: 0.65 | E4: 0.7 | F4: 0.75 | G4: 0.8 | L4: 0.45 | M4: 0.65 | N4: 0.7 | O4: 0.75 | P4: 0.8
B5: Particulars | C5: ='Feasibility Report'!O3 -> "45% additional area | D5: ='Feasibility Report'!Q3 -> "65% additional area | E5: ='Feasibility Report'!R3 -> "70% additioanl area | F5: ='Feasibility Report'!S3 -> "75% additional area | G5: ='Feasibility Report'!T3 -> "80% additional area | L5: "45% additional area | M5: "65% additional area | N5: "70% additioanl area | O5: "75% additional area | P5: "80% additional area
B6: AREA OF PLOT | C6: ='Feasibility Report'!O5 -> 1538.9 | D6: ='Feasibility Report'!Q5 -> 1538.9 | E6: ='Feasibility Report'!R5 -> 1538.9 | F6: ='Feasibility Report'!S5 -> 1538.9 | G6: ='Feasibility Report'!T5 -> 1538.9 | J6: Sale area in Sq ft | L6: =C26 -> 53449.21 | M6: =D26 -> 49605.278 | N6: =E26 -> 48644.295 | O6: =F26 -> 47683.312 | P6: =G26 -> 46722.33
B7: AREA OF PLOT IN POSSESSION | C7: ='Feasibility Report'!O6 -> 1538.9 | D7: ='Feasibility Report'!Q6 -> 1538.9 | E7: ='Feasibility Report'!R6 -> 1538.9 | F7: ='Feasibility Report'!S6 -> 1538.9 | G7: ='Feasibility Report'!T6 -> 1538.9
B8: ='Feasibility Report'!M13 -> New Net Plot Area | C8: ='Feasibility Report'!N13 -> 1465.9 | D8: ='Feasibility Report'!N13 -> 1465.9 | E8: ='Feasibility Report'!N13 -> 1465.9 | F8: ='Feasibility Report'!N13 -> 1465.9 | G8: ='Feasibility Report'!N13 -> 1465.9 | J8: Sale Proceeds
J9: Residential @ 55000 | L9: =L6*55000/10000000 -> 293.97065 | M9: =M6*55000/10000000 -> 272.82903 | N9: =N6*55000/10000000 -> 267.54362 | O9: =O6*55000/10000000 -> 262.25822 | P9: =P6*55000/10000000 -> 256.97281 | Q9: =L9*10000000/L6 -> 55000
B10: Existing BUA | C10: ='Feasibility Report'!N15 -> 1634.33 | D10: ='Feasibility Report'!N15 -> 1634.33 | E10: ='Feasibility Report'!N15 -> 1634.33 | F10: ='Feasibility Report'!N15 -> 1634.33 | G10: ='Feasibility Report'!N15 -> 1634.33 | J10: Commercial
J11: Parking Revenue @INR 25 lakhs | L11: =90*2500000/10000000 -> 22.5 | M11: =L11 -> 22.5 | N11: =M11 -> 22.5 | O11: =N11 -> 22.5 | P11: =O11 -> 22.5 | Q11: Assumed 90 parkings
B12: Existing Balcony Area | C12: ='Feasibility Report'!O17 -> 129.329 | D12: ='Feasibility Report'!O17 -> 129.329 | E12: ='Feasibility Report'!O17 -> 129.329 | F12: ='Feasibility Report'!O17 -> 129.329 | G12: ='Feasibility Report'!O17 -> 129.329 | L12: =SUM(L9:L11) -> 316.47065 | M12: =SUM(M9:M11) -> 295.32903 | N12: =SUM(N9:N11) -> 290.04362 | O12: =SUM(O9:O11) -> 284.75822 | P12: =SUM(P9:P11) -> 279.47281
B13: Existing CA Residential Flats: 33 | C13: ='Feasibility Report'!O18 -> 1498.33 | D13: ='Feasibility Report'!O18 -> 1498.33 | E13: ='Feasibility Report'!O18 -> 1498.33 | F13: ='Feasibility Report'!O18 -> 1498.33 | G13: ='Feasibility Report'!O18 -> 1498.33
B14: Existing CA Commercial Shops: 4 | C14: ='Feasibility Report'!O19 -> 138.424 | D14: ='Feasibility Report'!O19 -> 138.424 | E14: ='Feasibility Report'!O19 -> 138.424 | F14: ='Feasibility Report'!O19 -> 138.424 | G14: ='Feasibility Report'!O19 -> 138.424 | J14: Construction area | K14: Sq ft | L14: =C22*1.35*10.764 -> 120756.81 | M14: =D22*1.35*10.764 -> 120756.81 | N14: =E22*1.35*10.764 -> 120756.81 | O14: =F22*1.35*10.764 -> 120756.81 | P14: =G22*1.35*10.764 -> 120756.81
B15: Total Existing Carpet Area | C15: =C13+C14 -> 1636.754 | D15: =D13+D14 -> 1636.754 | E15: =E13+E14 -> 1636.754 | F15: =F13+F14 -> 1636.754 | G15: =G13+G14 -> 1636.754 | J15: (total BUA * 1.35 times)
B16: Existing BUA with balcony (1636.75 * 1.2) | C16: =C15*1.2 -> 1964.1048 | D16: =D15*1.2 -> 1964.1048 | E16: =E15*1.2 -> 1964.1048 | F16: =F15*1.2 -> 1964.1048 | G16: =G15*1.2 -> 1964.1048 | H16: Rate need to discuss with MS | J16: Constr. Cost @INR 4720 (including GST) | K16: =L14 -> 120756.81 | L16: =K16*4720/10000000 -> 56.997212 | M16: =L16 -> 56.997212 | N16: =M16 -> 56.997212 | O16: =N16 -> 56.997212 | P16: =O16 -> 56.997212 | Q16: =L16/3 -> 18.999071 | R16: =M16/3 -> 18.999071 | S16: =N16/3 -> 18.999071 | T16: =O16/3 -> 18.999071 | U16: =P16/3 -> 18.999071
H17: Rate need to discuss with MS | J17: Podium parking RCC work@INR 2950 | K17: 35779.79 | L17: =35780*2950/10000000 -> 10.5551 | M17: =L17 -> 10.5551 | N17: =M17 -> 10.5551 | O17: =N17 -> 10.5551 | P17: =O17 -> 10.5551 | Q17: =L17/3 -> 3.5183667 | R17: =M17/3 -> 3.5183667 | S17: =N17/3 -> 3.5183667 | T17: =O17/3 -> 3.5183667 | U17: =P17/3 -> 3.5183667
A18: A | B18: Proposed BUA Rehab ( Existing builtup area * additional area offered) | C18: =C16*(1+C4) -> 2847.952 | D18: =D16*(1+D4) -> 3240.7729 | E18: =E16*(1+E4) -> 3338.9782 | F18: =F16*(1+F4) -> 3437.1834 | G18: =G16*(1+G4) -> 3535.3886 | J18: Cost Escalation @ 5% | L18: =(L16+L17)*0.05 -> 3.3776156 | M18: =(M16+M17)*0.05 -> 3.3776156 | N18: =(N16+N17)*0.05 -> 3.3776156 | O18: =(O16+O17)*0.05 -> 3.3776156 | P18: =(P16+P17)*0.05 -> 3.3776156 | Q18: =L18/3 -> 1.1258719 | R18: =M18/3 -> 1.1258719 | S18: =N18/3 -> 1.1258719 | T18: =O18/3 -> 1.1258719 | U18: =P18/3 -> 1.1258719
J19: Construction cost 6% | L19: =((120757*4000)+(35780*2500))*6%/10000000 -> 3.434868 | M19: =((120757*4000)+(35780*2500))*6%/10000000 -> 3.434868 | N19: =((120757*4000)+(35780*2500))*6%/10000000 -> 3.434868 | O19: =((120757*4000)+(35780*2500))*6%/10000000 -> 3.434868 | P19: =((120757*4000)+(35780*2500))*6%/10000000 -> 3.434868 | Q19: =L19/3 -> 1.144956 | R19: =M19/3 -> 1.144956 | S19: =N19/3 -> 1.144956 | T19: =O19/3 -> 1.144956 | U19: =P19/3 -> 1.144956
A20: Main | B20: Total BUA proposed (plot area in Posession*4) | C20: =C7*4 -> 6155.6 | D20: =D7*4 -> 6155.6 | E20: =E7*4 -> 6155.6 | F20: =F7*4 -> 6155.6 | G20: =G7*4 -> 6155.6 | J20: TDR cost- 881.17 sq mt @ INR 122580 | L20: =('Feasibility Report'!T65+'Feasibility Report'!T66)/10000000 -> 7.4529535 | M20: =L20 -> 7.4529535 | N20: =M20 -> 7.4529535 | O20: =N20 -> 7.4529535 | P20: =O20 -> 7.4529535 | Q20: =L20 -> 7.4529535 | R20: =M20 -> 7.4529535 | S20: =N20 -> 7.4529535 | T20: =O20 -> 7.4529535 | U20: =P20 -> 7.4529535
B21: Fungible area (Proposed BUA * 0.35) | C21: =C20*0.35 -> 2154.46 | D21: =D20*0.35 -> 2154.46 | E21: =E20*0.35 -> 2154.46 | F21: =F20*0.35 -> 2154.46 | G21: =G20*0.35 -> 2154.46 | J21: SD on TDR @ 3% | L21: =L20*3% -> 0.2235886 | M21: =M20*3% -> 0.2235886 | N21: =N20*3% -> 0.2235886 | O21: =O20*3% -> 0.2235886 | P21: =P20*3% -> 0.2235886 | Q21: =L21 -> 0.2235886 | R21: =M21 -> 0.2235886 | S21: =N21 -> 0.2235886 | T21: =O21 -> 0.2235886 | U21: =P21 -> 0.2235886
A22: B | B22: Total BUA with fungible | C22: =C20+C21 -> 8310.06 | D22: =D20+D21 -> 8310.06 | E22: =E20+E21 -> 8310.06 | F22: =F20+F21 -> 8310.06 | G22: =G20+G21 -> 8310.06 | H22: =C22/C7 -> 5.4 | J22: 50 % Government FSI @INR 122580 | K22: 732.95 | L22: =(K22*122580*0.5)/10000000 -> 4.4922505 | M22: =(K22*122580*0.5)/10000000 -> 4.4922505 | N22: =(K22*122580*0.5)/10000000 -> 4.4922505 | O22: =(K22*122580*0.5)/10000000 -> 4.4922505 | P22: =(K22*122580*0.5)/10000000 -> 4.4922505 | Q22: =L22 -> 4.4922505 | R22: =M22 -> 4.4922505 | S22: =N22 -> 4.4922505 | T22: =O22 -> 4.4922505 | U22: =P22 -> 4.4922505
J23: Cost of Sale Fungible Area Rest @INR 122580 | K23: 1582.4445 | L23: =(K23*122580*0.5)/10000000 -> 9.6988023 | M23: =(K23*122580*0.5)/10000000 -> 9.6988023 | N23: =(K23*122580*0.5)/10000000 -> 9.6988023 | O23: =(K23*122580*0.5)/10000000 -> 9.6988023 | P23: =(K23*122580*0.5)/10000000 -> 9.6988023 | Q23: =L23 -> 9.6988023 | R23: =M23 -> 9.6988023 | S23: =N23 -> 9.6988023 | T23: =O23 -> 9.6988023 | U23: =P23 -> 9.6988023
B24: Sale BUA (B-A) | C24: =C22-C18 -> 5462.108 | D24: =D22-D18 -> 5069.2871 | E24: =E22-E18 -> 4971.0818 | F24: =F22-F18 -> 4872.8766 | G24: =G22-G18 -> 4774.6714 | J24: Commercial sale fungible area
B25: Sale Carpert area (BUA/1.1) | C25: =C24/1.1 -> 4965.5528 | D25: =D24/1.1 -> 4608.4428 | E25: =E24/1.1 -> 4519.1653 | F25: =F24/1.1 -> 4429.8878 | G25: =G24/1.1 -> 4340.6103 | J25: PAP purchase cost approx @ INR 1.7 lakhs | K25: 1245.72 | L25: =K25*170000/10000000 -> 21.17724 | M25: =K25*170000/10000000 -> 21.17724 | N25: =K25*170000/10000000 -> 21.17724 | O25: =K25*170000/10000000 -> 21.17724 | P25: =K25*170000/10000000 -> 21.17724 | Q25: =L25 -> 21.17724 | R25: =M25 -> 21.17724 | S25: =N25 -> 21.17724 | T25: =O25 -> 21.17724 | U25: =P25 -> 21.17724
B26: Sale Carpert area in sq ft | C26: =C25*10.764 -> 53449.21 | D26: =D25*10.764 -> 49605.278 | E26: =E25*10.764 -> 48644.295 | F26: =F25*10.764 -> 47683.312 | G26: =G25*10.764 -> 46722.33 | J26: Stamp duty on PAP @ 6% | K26: 0 | L26: =L25*6% -> 1.2706344 | M26: =M25*6% -> 1.2706344 | N26: =N25*6% -> 1.2706344 | O26: =O25*6% -> 1.2706344 | P26: =P25*6% -> 1.2706344 | Q26: =L26 -> 1.2706344 | R26: =M26 -> 1.2706344 | S26: =N26 -> 1.2706344 | T26: =O26 -> 1.2706344 | U26: =P26 -> 1.2706344
J27: Difference in premium RR approx @ INR 20000 | K27: 1245.72 | L27: =K27*20000*0.4/10000000 -> 0.996576 | M27: =K27*20000*0.4/10000000 -> 0.996576 | N27: =K27*20000*0.4/10000000 -> 0.996576 | O27: =K27*20000*0.4/10000000 -> 0.996576 | P27: =K27*20000*0.4/10000000 -> 0.996576 | Q27: =L27 -> 0.996576 | R27: =M27 -> 0.996576 | S27: =N27 -> 0.996576 | T27: =O27 -> 0.996576 | U27: =P27 -> 0.996576
C28: Units | D28: Sq ft | J28: Muncipal Exp
B29: Residential | C29: 33 | D29: ='Feasibility Report'!O18*10.764 -> 16128.024 | J29: Scrutiny fees (Total BUA with fungible FSI) * RR | L29: ='Feasibility Report'!T75/10000000 -> 0.2493018 | M29: =L29 -> 0.2493018 | N29: =M29 -> 0.2493018 | O29: =N29 -> 0.2493018 | P29: =O29 -> 0.2493018 | Q29: =L29 -> 0.2493018 | R29: =M29 -> 0.2493018 | S29: =N29 -> 0.2493018 | T29: =O29 -> 0.2493018 | U29: =P29 -> 0.2493018
B30: Commercial | C30: 4 | D30: ='Feasibility Report'!O19*10.764 -> 1489.9959 | J30: I.O.D Deposit | L30: ='Feasibility Report'!T76/10000000 -> 0.0089448785 | M30: =L30 -> 0.0089448785 | N30: =M30 -> 0.0089448785 | O30: =N30 -> 0.0089448785 | P30: =O30 -> 0.0089448785 | Q30: =L30 -> 0.0089448785 | R30: =M30 -> 0.0089448785 | S30: =N30 -> 0.0089448785 | T30: =O30 -> 0.0089448785 | U30: =P30 -> 0.0089448785
C31: =SUM(C29:C30) -> 37 | D31: =SUM(D29:D30) -> 17618.02 | J31: Debris Deposit (Rs. 45,000 max) | L31: ='Feasibility Report'!T77/10000000 -> 0.0045 | M31: =L31 -> 0.0045 | N31: =M31 -> 0.0045 | O31: =N31 -> 0.0045 | P31: =O31 -> 0.0045 | Q31: =L31 -> 0.0045 | R31: =M31 -> 0.0045 | S31: =N31 -> 0.0045 | T31: =O31 -> 0.0045 | U31: =P31 -> 0.0045
J32: Development charges 4% for built up area | L32: ='Feasibility Report'!T78/10000000 -> 3.9605633 | M32: =L32 -> 3.9605633 | N32: =M32 -> 3.9605633 | O32: =N32 -> 3.9605633 | P32: =O32 -> 3.9605633 | Q32: =L32 -> 3.9605633 | R32: =M32 -> 3.9605633 | S32: =N32 -> 3.9605633 | T32: =O32 -> 3.9605633 | U32: =P32 -> 3.9605633
B33: Rental ( Higher side) | C33: Per Sq ft | D33: Y1 | E33: Y2 | F33: Y3 | J33: Dev charges on commercial area | L33: ='Feasibility Report'!T79/10000000 -> 0 | M33: =L33 -> 0 | N33: =M33 -> 0 | O33: =N33 -> 0 | P33: =O33 -> 0 | Q33: =L33 -> 0 | R33: =M33 -> 0 | S33: =N33 -> 0 | T33: =O33 -> 0 | U33: =P33 -> 0
B34: Residential | C34: 150 | D34: =D29*C34*12 -> 29030443 | E34: =D34*1.1 -> 31933488 | F34: =E34*1.1 -> 35126837 | J34: Development charges 1% of land component (New Plot area * 1%) | L34: ='Feasibility Report'!T80/10000000 -> 0.17969002 | M34: =L34 -> 0.17969002 | N34: =M34 -> 0.17969002 | O34: =N34 -> 0.17969002 | P34: =O34 -> 0.17969002 | Q34: =L34 -> 0.17969002 | R34: =M34 -> 0.17969002 | S34: =N34 -> 0.17969002 | T34: =O34 -> 0.17969002 | U34: =P34 -> 0.17969002
B35: Commercial | C35: 300 | D35: =D30*C35*12 -> 5363985.4 | E35: =D35*1.1 -> 5900383.9 | F35: =E35*1.1 -> 6490422.3 | J35: Dev charges commercial area land component | L35: ='Feasibility Report'!T81/10000000 -> 0.010057074 | M35: =L35 -> 0.010057074 | N35: =M35 -> 0.010057074 | O35: =N35 -> 0.010057074 | P35: =O35 -> 0.010057074 | Q35: =L35 -> 0.010057074 | R35: =M35 -> 0.010057074 | S35: =N35 -> 0.010057074 | T35: =O35 -> 0.010057074 | U35: =P35 -> 0.010057074
B36: Brokerage 1 month | C36: Residential | D36: =C34*D29 -> 2419203.6 | J36: =K36*10.7639 -> 0 | L36: ='Feasibility Report'!T82/10000000 -> 0 | M36: =L36 -> 0 | N36: =M36 -> 0 | O36: =N36 -> 0 | P36: =O36 -> 0 | Q36: =L36 -> 0 | R36: =M36 -> 0 | S36: =N36 -> 0 | T36: =O36 -> 0 | U36: =P36 -> 0
B37: Brokerage 1 month | C37: Commercial | D37: =C35*D30 -> 446998.78 | J37: Labour welfare cess (total construction area * 0.01* rate) | L37: ='Feasibility Report'!T83/10000000 -> 0.35633579 | M37: =L37 -> 0.35633579 | N37: =M37 -> 0.35633579 | O37: =N37 -> 0.35633579 | P37: =O37 -> 0.35633579 | Q37: =L37 -> 0.35633579 | R37: =M37 -> 0.35633579 | S37: =N37 -> 0.35633579 | T37: =O37 -> 0.35633579 | U37: =P37 -> 0.35633579
B38: Shifting @ INR 30 k one time | D38: =30000*C31 -> 1110000 | J38: Open space Deficiency approx | L38: ='Feasibility Report'!T84/10000000 -> 15 | M38: =L38 -> 15 | N38: =M38 -> 15 | O38: =N38 -> 15 | P38: =O38 -> 15 | Q38: =L38 -> 15 | R38: =M38 -> 15 | S38: =N38 -> 15 | T38: =O38 -> 15 | U38: =P38 -> 15
D39: =SUM(D34:D38) -> 38370631 | E39: =SUM(E34:E38) -> 37833872 | F39: =SUM(F34:F38) -> 41617259 | J39: Staircase premium | L39: ='Feasibility Report'!T85/10000000 -> 5.0932358 | M39: =L39 -> 5.0932358 | N39: =M39 -> 5.0932358 | O39: =N39 -> 5.0932358 | P39: =O39 -> 5.0932358 | Q39: =L39 -> 5.0932358 | R39: =M39 -> 5.0932358 | S39: =N39 -> 5.0932358 | T39: =O39 -> 5.0932358 | U39: =P39 -> 5.0932358
C40: In crores | D40: =D39/10000000 -> 3.8370631 | E40: =E39/10000000 -> 3.7833872 | F40: =F39/10000000 -> 4.1617259 | J40: Water and Sewerage Charges (total construction area * rate) | L40: ='Feasibility Report'!T86/10000000 -> 0.57214763 | M40: =L40 -> 0.57214763 | N40: =M40 -> 0.57214763 | O40: =N40 -> 0.57214763 | P40: =O40 -> 0.57214763 | Q40: =L40 -> 0.57214763 | R40: =M40 -> 0.57214763 | S40: =N40 -> 0.57214763 | T40: =O40 -> 0.57214763 | U40: =P40 -> 0.57214763
C41: Total | F41: =SUM(D40:F40) -> 11.782176 | J41: Infra improvement charges (TDR to be purchased * rate) | L41: ='Feasibility Report'!T87/10000000 -> 0.13994301 | M41: =L41 -> 0.13994301 | N41: =M41 -> 0.13994301 | O41: =N41 -> 0.13994301 | P41: =O41 -> 0.13994301 | Q41: =L41 -> 0.13994301 | R41: =M41 -> 0.13994301 | S41: =N41 -> 0.13994301 | T41: =O41 -> 0.13994301 | U41: =P41 -> 0.13994301
...

Sheet Feasibility Report
M1: Feasibility Report For Dharti CHS Ltd., situated at Versova, Mumbai.
C2: B)AREA OF PLOT IN POSSESSION | E2: 10.7639 | P2: Typed Figures
O3: "45% additional area | Q3: "65% additional area | R3: "70% additioanl area | S3: "75% additional area | T3: "80% additional area
D4: Area in Sq mt | E4: Area in Sq ft | M4: Particulars | N4: Area in Sq mt | O4: Area in Sq mt | P4: Area in Sq ft | Q4: Area in Sq mt | R4: Area in Sq mt | S4: Area in Sq mt | T4: Area in Sq mt
B5: 1) | C5: A)AREA OF PLOT | D5: 1538.9 | E5: =D5*10.7639-9.76 -> 16554.806 | G5: 1538.90*10.7639-9.76 | K5: A | M5: AREA OF PLOT | O5: 1538.9 | P5: =O5*10.7639-9.76 -> 16554.806 | Q5: 1538.9 | R5: =Q5 -> 1538.9 | S5: =R5 -> 1538.9 | T5: =S5 -> 1538.9
C6: B)AREA OF PLOT IN POSSESSION | D6: =D5 -> 1538.9 | E6: =E5 -> 16554.806 | M6: AREA OF PLOT IN POSSESSION | O6: =O5 -> 1538.9 | P6: =P5 -> 16554.806 | Q6: =Q5 -> 1538.9 | R6: =Q6 -> 1538.9 | S6: =R6 -> 1538.9 | T6: =S6 -> 1538.9
B8: 2) | C8: Deduction for | M8: Old Plot area approve plan | N8: 1635
C9: A)30 MT DP ROAD | D9: 0 | M9: Less: Old set back Area (Road width 18.3m) | N9: 108.14
C10: B)AMENITY SPACE | D10: =SUM(D9:D9) -> 0 | M10: Old Net Plot Area | N10: =N8-N9 -> 1526.86
C11: C)AREA UNDER ENCROCHMENT | D11: 0
C12: TOTAL DEDUCTION | D12: 0 | M12: Less: New set back Area | N12: 73
M13: New Net Plot Area | N13: =O6-N12 -> 1465.9
B14: 3) | C14: BALANCE AREA OF PLOT(1 ,2) | D14: =D6-D12 -> 1538.9 | E14: =E6-G12 -> 16554.806
C15: Deduction Recreation Ground as per rule @15% | D15: 0 | M15: Existing BUA | N15: 1634.33 | W15: As per existing approved plan
C16: Net area of plot | D16: =D14-D15 -> 1538.9 | E16: =E14-E15 -> 16554.806
C17: Additional for floor space index road | D17: 0 | K17: B | M17: Existing Balcony Area | O17: 129.329 | P17: =O17*10.7639+0.02 -> 1392.1044 | Q17: 129.329 | R17: =Q17 -> 129.329 | S17: =R17 -> 129.329 | T17: =S17 -> 129.329 | W17: 278.42*5
B18: 4) | C18: TOTAL USABLE CARPET AREA OF SOCIETY | D18: =D5-D17 -> 1538.9 | E18: =E5-E17 -> 16554.806 | M18: Existing CA Residential Flats: 33 | O18: 1498.33 | P18: =O18*10.7639+0.13 -> 16128.004 | Q18: 1498.33 | R18: =Q18 -> 1498.33 | S18: =R18 -> 1498.33 | T18: =S18 -> 1498.33
M19: Existing CA Commercial Shops: 4 | O19: 138.424 | P19: =O19*10.7639+0.02 -> 1490.0021 | Q19: 138.424 | R19: =Q19 -> 138.424 | S19: =R19 -> 138.424 | T19: =S19 -> 138.424
B20: 5) | C20: Maximum permissible FSI as per Table 6G-UDCPR | M20: Total Existing Carpet Area | O20: =O18+O19 -> 1636.754 | P20: =O20*10.7639 -> 17617.856 | Q20: =Q18+Q19 -> 1636.754 | R20: =Q20 -> 1636.754 | S20: =R20 -> 1636.754 | T20: =S20 -> 1636.754
B21: a) | C21: Basic FSI of 1.1 (2504.22 *1.1) | D21: =D18*1.1 -> 1692.79 | E21: =D21*10.7639-10.74 -> 18210.282 | G21: Flats | M21: Existing BUA with balcony (1636.75 * 1.2) | O21: =+O20*1.2-0.002236 -> 1964.1026 | P21: =O21*10.7639 -> 21141.404 | Q21: =+Q20*1.2-0.002236 -> 1964.1026 | R21: =R20*1.2 -> 1964.1048 | S21: =S20*1.2 -> 1964.1048 | T21: =T20*1.2 -> 1964.1048
B22: b) | C22: 15 sq.mt PER TENANT INCENTIVE - UDCPR 7.6.1.(i) (____ X 15)-IF APPLICABLE | D22: 3756.33 | E22: =D22*10.7639-14.65 -> 40418.11 | G22: =D22/15 -> 250.422
B23: c) | C23: F.S.I ON PAYMENT OF PREMIUM - 0.5 (2504.22X0.5) for 18.43 m wide road as per old DP | D23: =D6*0.5 -> 769.45 | E23: =D23*10.7639-4.89 -> 8277.3929 | K23: C | M23: Permissible FSI :
B24: d) | C24: T.D.R TO BE PURCHASED - 6.75 (2504.22X0.9) for 18.43 m wide road as per old DP | D24: =D6*0.9 -> 1385.01 | E24: =D24*10.7639-8.79 -> 14899.319 | M24: 2.4 proposed BUA (2.4 * 1465.9) (Plot area * 2.4) | O24: =N13*2.4 -> 3518.16 | P24: =O24*10.7639 -> 37869.122 | Q24: =N13*2.4 -> 3518.16 | R24: =N13*2.4 -> 3518.16 | S24: =N13*2.4 -> 3518.16 | T24: =N13*2.4 -> 3518.16 | W24: as per road with
C25: TOTAL FSI | D25: =SUM(D21:D24) -> 7603.58 | E25: =SUM(E21:E24) -> 81805.105 | F25: =E25/D25 -> 10.758762 | G25: =SUM(G21:G24)+0.01 -> 250.432 | M25: Add: Set back Area (2 * 73) (Set back area * 2) | O25: =N12*2 -> 146 | P25: =O25*10.7639 -> 1571.5294 | Q25: =N12*2 -> 146 | R25: =N12*2 -> 146 | S25: =N12*2 -> 146 | T25: =N12*2 -> 146
M26: Proposed BUA | O26: =SUM(O24:O25) -> 3664.16 | P26: =SUM(P24:P25) -> 39440.652 | Q26: =SUM(Q24:Q25) -> 3664.16 | R26: =SUM(R24:R25) -> 3664.16 | S26: =SUM(S24:S25) -> 3664.16 | T26: =SUM(T24:T25) -> 3664.16
B27: e) | C27: F.S.I CONSUMED FOR RESIDENTIAL=72 | D27: 2727.3 | E27: =D27*10.7639-10.61 -> 29345.774 | F27: =E27/D27 -> 10.76001 | W27: Sec 33 -11 | X27: SRA scheme
B28: f) | C28: ANCILLARY F.S.I- 0.6 ON RESIDENTIAL AREA (2727.3*0.6) | D28: =D27*0.6 -> 1636.38 | E28: =D28*10.7639-6.37 -> 17607.461 | I28: *** | L28: a | M28: Proposed BUA Rehab ( Existing builtup area * additional area offered) | O28: =O21*1.45 -> 2847.9487 | P28: =O28*10.7639 -> 30655.035 | Q28: =Q21*1.65 -> 3240.7692 | R28: =R21*1.7 -> 3338.9782 | S28: =S21*1.75 -> 3437.1834 | T28: =T21*1.8 -> 3535.3886 | W28: 45% Additional Area
B29: g) | C29: TOTAL B.U.A FOR RESIDENTIAL PURPOSE (E+F) INCLUDING BALCON | D29: =D27+D28 -> 4363.68 | E29: =E27+E28 -> 46953.235 | L29: b | M29: Rehab Fungible Area (existing BUA * 0.35) | O29: =N15*0.35 -> 572.0155 | P29: =O29*10.7639 -> 6157.1176 | Q29: =N15*0.35 -> 572.0155 | R29: =N15*0.35 -> 572.0155 | S29: =N15*0.35 -> 572.0155 | T29: =N15*0.35 -> 572.0155
L30: c | M30: Proposed Rehab CA (2847.948718 / 1.2) | O30: =O28/1.2 -> 2373.2906 | P30: =O30*10.7639 -> 25545.863 | Q30: =Q28/1.2 -> 2700.641 | R30: =R28/1.2 -> 2782.4818 | S30: =S28/1.2 -> 2864.3195 | T30: =T28/1.2 -> 2946.1572
B31: h) | C31: F.S.I TO BE CONSUMED FOR COMMERCIAL 12 | D31: 220.66 | E31: =D31*10.7639+0.04 -> 2375.2022 | F31: 2375.2
B32: i) | C32: ANCILLARY F.SI- 0.8 ON COMMERCIAL AREA (220.66*0.8) | D32: =D31*0.8 -> 176.528 | E32: =D32*10.7639+0.01 -> 1900.1397 | K32: D | M32: Govt FSI : plot area x 0.5 (0.5 * 1465.9) (Plot area * 0.5) | O32: =N13*0.5 -> 732.95 | P32: =O32*10.7639 -> 7889.4005 | Q32: =N13*0.5 -> 732.95 | R32: =N13*0.5 -> 732.95 | S32: =N13*0.5 -> 732.95 | T32: =N13*0.5 -> 732.95 | W32: Purchase from BMC
B33: j) | C33: TOTAL B.U.A FOR COMMERCIAL PURPOSE (H+I) | D33: =D31+D32 -> 397.188 | E33: =E31+E32 -> 4275.3419
K34: E | M34: TDR: plot area x 0.9 (0.9 * 1465.9) (Plot area * 0.9) | O34: =N13*0.9 -> 1319.31 | P34: =O34*10.7639 -> 14200.921 | Q34: =N13*0.9 -> 1319.31 | R34: =N13*0.9 -> 1319.31 | S34: =N13*0.9 -> 1319.31 | T34: =N13*0.9 -> 1319.31
C35: MAX PERMISSIBLE FSI (g+j) | D35: =D29+D33 -> 4760.868 | E35: =E29+E33+17.45 -> 51246.027 | L35: a | M35: TDR to be purchased (1319.31 sqm - incentive: 33 Flats x 10 sqm - 108.14 sqm) | O35: =O34-(33*10)-108.14 -> 881.17 | P35: =O35*10.7639 -> 9484.8258 | Q35: =Q34-(33*10)-108.14 -> 881.17 | R35: =R34-(33*10)-108.14 -> 881.17 | S35: =S34-(33*10)-108.14 -> 881.17 | T35: =T34-(33*10)-108.14 -> 881.17 | W35: Need to ask 108.14 sqmt
C37: CARPET AREA 72+12 | K37: F | M37: Proposed bua rehab commer. (exis carpet area comme * 1.2 * 1.4) | O37: =(O19+0.0043776)*1.2*1.4-0.00672 -> 232.55295 | P37: =O37*10.7639 -> 2503.1767 | Q37: =(Q19+0.0043776)*1.2*1.4-0.00672 -> 232.55295 | R37: =(R19+0.0043776)*1.2*1.4-0.00672 -> 232.55295 | S37: =(S19+0.0043776)*1.2*1.4-0.00672 -> 232.55295 | T37: =(T19+0.0043776)*1.2*1.4-0.00672 -> 232.55295 | V37: 0.006720068
B38: a) | C38: RESIDENTIAL CARPET AREA (g *0.78) | D38: =D29*0.78 -> 3403.6704 | E38: =D38*10.7639 -> 36636.768
B39: b) | C39: COMMERCIAL CARPET AREA (Ij * 0.82) | D39: =D33*0.82 -> 325.69416 | E39: =D39*10.7639 -> 3505.7394 | K39: G | M39: 33f20b : permissible BUA (4 * 1538.9) (plot area in Posession*4) | O39: =O6*4 -> 6155.6 | P39: =O39*10.7639 -> 66258.263 | Q39: =Q6*4 -> 6155.6 | R39: =O6*4 -> 6155.6 | S39: =O6*4 -> 6155.6 | T39: =O6*4 -> 6155.6
C40: TOTAL AVAILABLE CARPET AREA IN PROJECT | D40: =SUM(D38:D39) -> 3729.3646 | E40: =SUM(E38:E39) -> 40142.507 | M40: Less: BUA under 33/7b | O40: 3664.16 | P40: =O40*10.7639 -> 39440.652 | Q40: 3664.16 | R40: 3664.16 | S40: 3664.16 | T40: 3664.16
C41: EXISTING CARPET AREA OF THE SOCIETY | M41: Balance BUA | O41: =O39-O40 -> 2491.44 | P41: =O41*10.7639 -> 26817.611 | Q41: =Q39-Q40 -> 2491.44 | R41: =R39-R40 -> 2491.44 | S41: =S39-S40 -> 2491.44 | T41: =T39-T40 -> 2491.44
B42: a) | C42: RESIDENTIAL CARPET AREA (72NO.S OF RESIDENTIAL TENANTS) | D42: 3840.04 | E42: =D42*10.7639+0.4 -> 41334.207
...

Sheet Area & Cmpsn to Exstng Mmbr
B2: Area to Existing Members
B3: Particulars | C3: Sqmt | D3: Sqft
B4: Existing Balcony Area | C4: 129.329 | D4: =C4*10.7639+0.02 -> 1392.1044
B5: Existing CA Residential Flats: 33 | C5: 1498.33 | D5: =C5*10.7639+0.13 -> 16128.004
B6: Existing CA Commercial Shops: 4 | C6: 138.424 | D6: =C6*10.7639+0.02 -> 1490.0021
B7: Toal Existing Carpet Area | C7: =C5+C6 -> 1636.754 | D7: =C7*10.7639 -> 17617.856
B8: Existing BUA with balcony (1636.75 * 1.2) | C8: =+C7*1.2-0.002236 -> 1964.1026 | D8: =C8*10.7639 -> 21141.404
B9: Additiona Area (1964.1 * 0.45) | C9: =C8*0.45 -> 883.84615 | D9: =C9*10.7639 -> 9513.6316
B10: Proposed BUA Rehab (1.45 * 1964.102564) | C10: =C8+C9 -> 2847.9487 | D10: =C10*10.7639 -> 30655.035
B12: Compensation or Cost to Existing Members
B13: Particulars | C13: Sqmt | D13: Sqft | E13: No. of Members | F13: No. of Months | G13: Cost per Unit | H13: Total Cost
B14: Corpus to members | C14: 0 | D14: ='Area & Cmpsn to Exstng Mmbr'!D7+0.14 -> 17617.996 | E14: 0 | F14: 0 | G14: 1500 | H14: =D14*G14 -> 26426995
B15: Transit Accommodation residential | C15: ='Feasibility Report'!N103 -> 1498.33 | D15: =C15*10.7639+0.13 -> 16128.004 | E15: 0 | F15: 36 | G15: 125 | H15: =D15*F15*G15 -> 72576019
B16: Commercial | C16: 138.424 | D16: 1490.0021 | E16: 0 | F16: 36 | G16: 200 | H16: =D16*F16*G16 -> 10728015
B17: One month Brokerage (transit) | C17: 0 | D17: 17617.996 | E17: 0 | F17: 1 | G17: 125 | H17: =D17*F17*G17 -> 2202249.5
B18: Shifting Charges | C18: 0 | D18: 0 | E18: 37 | F18: 0 | G18: 30000 | H18: =E18*G18 -> 1110000
B19: Total | H19: =SUM(H14:H18) -> 1.1304328e+08
E24: Total Cost | F24: Admin / marketing / site expenses | G24: Interest On Initial Investment | H24: Total Cost other than Admin / marketing / site expenses
E25: 1.9128194e+09 | F25: 70000000 | G25: 150000000 | H25: =E25-F25-G25 -> 1.6928194e+09
B27: Total Finance Cost
B28: Particulars | C28: Amount
B29: TDR Cost : slum TDR | C29: 18362349
B30: General TDR | C30: 56167186
B31: Stamp duty on TDR | C31: 2235886
B32: 50 % Government FSI | C32: 44922506
B33: Total Municipal Expense | C33: =SUM('Feasibility Report'!T75:T97) -> 2.9744272e+08
B34: Total Other Cost | C34: =(H25-SUM(C29:C33))/3 -> 4.2456291e+08
B35: Admin / marketing / site expenses | C35: ='Feasibility Report'!T116*0.04 -> 1.219074e+08
C36: =SUM(C29:C35) -> 9.6560096e+08
B38: Finance cost @ 12% | C38: =C36*0.12 -> 1.1587212e+08
